Workbook

Sheet WBS Input
A1: Project WBS | D1: Ver.0.0
D2: 46125
A4: Phase | B4: ID | C4: Task Name | D4: Details | E4: Owner | F4: Planned Start | G4: Planned End | H4: Actual Start | I4: Actual End | J4: Status | K4: Notes
A5: 1. Planning & Current State Analysis
B6: 1.1 | C6: Current Operations Inventory | D6: Define scope of target business operations | E6: Alice | F6: 46113 | G6: 46143 | H6: 46113 | J6: In Progress
B7: 1.1.1 | C7: Revise Current Business Process Flowcharts | D7: Update and visualize payroll, social insurance, and attendance processes | E7: Alice | F7: 46113 | G7: 46143 | H7: 46115 | J7: In Progress | K7: Manage the full process flowchart revision (1.1.1) and individual operations inventory sheets (1.1.5 onward) as separate deliverables (suited for large projects). Alternatively, organize by business area within the flowchart revision (suited for small to mid-size projects).
B8: 1.1.2 | C8: Review Current SLA & Performance Evaluation | D8: Identify current vendor performance gaps and unmet items | E8: Bob | F8: 46113 | G8: 46127 | J8: Not Started
B9: 1.1.3 | C9: Create RACI Responsibility Matrix | D9: Clarify responsibilities among internal HR, IT, and current vendor
B10: 1.1.4 | C10: Identify Exception & Non-Standard Processes | D10: Identify undocumented special handling procedures
B11: 1.1.5 | C11: Review Social Insurance & Labor Insurance Operations | D11: Map health insurance and pension enrollment/disenrollment, standard remuneration, and monthly changes | K11: Add individual outsourced operations from 1.1.5 onward
B12: 1.1.6 | C12: Review Resignation & Leave of Absence Procedures | D12: Visualize severance pay calculations, separation certificates, parental/sick leave benefits
B13: 1.1.7 | C13: Review Benefits-Related Administrative Tasks | D13: Organize allowances, ESOP, savings plans, health check booking coordination, etc.
B14: 1.1.8 | C14: Review Year-End Tax Adjustment Processes | D14: Identify year-end adjustment schedule, filing systems, and e-filing usage
B15: 1.1.9 | C15: abcdef | D15: aaaaaa
B16: 1.1.10 | C16: ghijk | D16: bbbbbb
B17: 1.3 | C17: Budget & Schedule Planning | D17: Obtain approval for project execution plan
B18: 1.3.1 | C18: Estimate Transition Costs | D18: Compare initial implementation costs vs. ongoing operating costs
B19: 1.3.2 | C19: Create Project Roadmap | D19: Create timeline from RFP issuance through go-live
B20: 1.3.3 | C20: Develop Resource Plan | D20: Secure internal team capacity and establish project structure
A21: 2. Vendor Selection
B22: 2.1 | C22: Prepare & Send RFI/RFP | D22: Distribute RFP and manage Q&A process
B23: 2.2 | C23: Evaluate Proposals & Select Vendor | D23: Conduct presentations and score-based selection
A24: 3. Transition Preparation (Design)
B25: 3.1 | C25: Design To-Be Business Processes | D25: Optimize operations under new vendor structure
B26: 3.1.1 | C26: Gap Analysis of Business Processes | D26: Identify gaps between current and new vendor standard capabilities
B27: 3.1.2 | C27: Redesign Approval Workflows | D27: Configure approval routes and HRIS permissions
B28: 3.2 | C28: System/Data Integration Design | D28: Ensure data integrity
B29: 3.2.1 | C29: Create Interface Specifications | D29: Define integration points with HCM, payroll systems, etc.
B30: 3.2.2 | C30: Master Data Mapping | D30: Reconcile organization codes, names, and attribute definitions
B31: 3.3 | C31: Develop Migration Plan | D31: Minimize transition risks
B32: 3.3.1 | C32: Data Cleansing Plan | D32: Identify HR data requiring correction before migration
B33: 3.3.2 | C33: Parallel Run Plan | D33: Define payroll dual-verification period and test population
A34: 4. Build & Test
B35: 4.1 | C35: User Acceptance Testing (UAT) | D35: Operational testing based on business scenarios
A36: 5. Migration & Parallel Run
B37: 5.1 | C37: Execute Parallel Run | D37: Reconcile payroll calculations between current and new vendor
B38: 5.2 | C38: Go-Live Cutover | D38: Complete transition to new vendor
A39: 6. ABC
B40: 6.1 | C40: abcdef | D40: cccccc
B41: 6.2 | C41: ghijk | D41: dddddd

Sheet WBS Tree View
A1: ='WBS Input'!A1&" Tree" -> Project WBS Tree | C1: ='WBS Input'!D1 -> Ver.0.0
C2: ='WBS Input'!D2 -> 46125
A4: ID | B4: Phase / Task Name | C4: Details | D4: Owner | E4: ステータス
A5: =IF(AND('WBS Input'!A5="",'WBS Input'!B5=""),"",IF('WBS Input'!A5<>"","★",'WBS Input'!B5)) -> ★ | B5: =IF(AND('WBS Input'!A5="",'WBS Input'!B5=""),"",IF('WBS Input'!A5<>"","■ "&'WBS Input'!A5,IF(LEN('WBS Input'!B5)-LEN(SUBSTITUTE('WBS Input'!B5,".",""))<=1," ├─ "&'WBS Input'!C5," │ ├─ "&'WBS Input'!C5))) -> ■ 1. Planning & Current State Analysis | C5: =IF(AND('WBS Input'!A5="",'WBS Input'!B5=""),"",IF('WBS Input'!A5<>"","",'WBS Input'!D5)) | D5: =IF(AND('WBS Input'!A5="",'WBS Input'!B5=""),"",IF('WBS Input'!A5<>"","",IF('WBS Input'!E5="","",'WBS Input'!E5))) | E5: =IF(AND('WBS Input'!A5="",'WBS Input'!B5=""),"",IF('WBS Input'!A5<>"","",IF('WBS Input'!J5="","",'WBS Input'!J5)))
A6: =IF(AND('WBS Input'!A6="",'WBS Input'!B6=""),"",IF('WBS Input'!A6<>"","★",'WBS Input'!B6)) -> 1.1 | B6: =IF(AND('WBS Input'!A6="",'WBS Input'!B6=""),"",IF('WBS Input'!A6<>"","■ "&'WBS Input'!A6,IF(LEN('WBS Input'!B6)-LEN(SUBSTITUTE('WBS Input'!B6,".",""))<=1," ├─ "&'WBS Input'!C6," │ ├─ "&'WBS Input'!C6))) -> ├─ Current Operations Inventory | C6: =IF(AND('WBS Input'!A6="",'WBS Input'!B6=""),"",IF('WBS Input'!A6<>"","",'WBS Input'!D6)) -> Define scope of target business operations | D6: =IF(AND('WBS Input'!A6="",'WBS Input'!B6=""),"",IF('WBS Input'!A6<>"","",IF('WBS Input'!E6="","",'WBS Input'!E6))) -> Alice | E6: =IF(AND('WBS Input'!A6="",'WBS Input'!B6=""),"",IF('WBS Input'!A6<>"","",IF('WBS Input'!J6="","",'WBS Input'!J6))) -> In Progress
A7: =IF(AND('WBS Input'!A7="",'WBS Input'!B7=""),"",IF('WBS Input'!A7<>"","★",'WBS Input'!B7)) -> 1.1.1 | B7: =IF(AND('WBS Input'!A7="",'WBS Input'!B7=""),"",IF('WBS Input'!A7<>"","■ "&'WBS Input'!A7,IF(LEN('WBS Input'!B7)-LEN(SUBSTITUTE('WBS Input'!B7,".",""))<=1," ├─ "&'WBS Input'!C7," │ ├─ "&'WBS Input'!C7))) -> │ ├─ Revise Current Business Process Flowcharts | C7: =IF(AND('WBS Input'!A7="",'WBS Input'!B7=""),"",IF('WBS Input'!A7<>"","",'WBS Input'!D7)) -> Update and visualize payroll, social insurance, and attendance processes | D7: =IF(AND('WBS Input'!A7="",'WBS Input'!B7=""),"",IF('WBS Input'!A7<>"","",IF('WBS Input'!E7="","",'WBS Input'!E7))) -> Alice | E7: =IF(AND('WBS Input'!A7="",'WBS Input'!B7=""),"",IF('WBS Input'!A7<>"","",IF('WBS Input'!J7="","",'WBS Input'!J7))) -> In Progress
A8: =IF(AND('WBS Input'!A8="",'WBS Input'!B8=""),"",IF('WBS Input'!A8<>"","★",'WBS Input'!B8)) -> 1.1.2 | B8: =IF(AND('WBS Input'!A8="",'WBS Input'!B8=""),"",IF('WBS Input'!A8<>"","■ "&'WBS Input'!A8,IF(LEN('WBS Input'!B8)-LEN(SUBSTITUTE('WBS Input'!B8,".",""))<=1," ├─ "&'WBS Input'!C8," │ ├─ "&'WBS Input'!C8))) -> │ ├─ Review Current SLA & Performance Evaluation | C8: =IF(AND('WBS Input'!A8="",'WBS Input'!B8=""),"",IF('WBS Input'!A8<>"","",'WBS Input'!D8)) -> Identify current vendor performance gaps and unmet items | D8: =IF(AND('WBS Input'!A8="",'WBS Input'!B8=""),"",IF('WBS Input'!A8<>"","",IF('WBS Input'!E8="","",'WBS Input'!E8))) -> Bob | E8: =IF(AND('WBS Input'!A8="",'WBS Input'!B8=""),"",IF('WBS Input'!A8<>"","",IF('WBS Input'!J8="","",'WBS Input'!J8))) -> Not Started
A9: =IF(AND('WBS Input'!A9="",'WBS Input'!B9=""),"",IF('WBS Input'!A9<>"","★",'WBS Input'!B9)) -> 1.1.3 | B9: =IF(AND('WBS Input'!A9="",'WBS Input'!B9=""),"",IF('WBS Input'!A9<>"","■ "&'WBS Input'!A9,IF(LEN('WBS Input'!B9)-LEN(SUBSTITUTE('WBS Input'!B9,".",""))<=1," ├─ "&'WBS Input'!C9," │ ├─ "&'WBS Input'!C9))) -> │ ├─ Create RACI Responsibility Matrix | C9: =IF(AND('WBS Input'!A9="",'WBS Input'!B9=""),"",IF('WBS Input'!A9<>"","",'WBS Input'!D9)) -> Clarify responsibilities among internal HR, IT, and current vendor | D9: =IF(AND('WBS Input'!A9="",'WBS Input'!B9=""),"",IF('WBS Input'!A9<>"","",IF('WBS Input'!E9="","",'WBS Input'!E9))) | E9: =IF(AND('WBS Input'!A9="",'WBS Input'!B9=""),"",IF('WBS Input'!A9<>"","",IF('WBS Input'!J9="","",'WBS Input'!J9)))
A10: =IF(AND('WBS Input'!A10="",'WBS Input'!B10=""),"",IF('WBS Input'!A10<>"","★",'WBS Input'!B10)) -> 1.1.4 | B10: =IF(AND('WBS Input'!A10="",'WBS Input'!B10=""),"",IF('WBS Input'!A10<>"","■ "&'WBS Input'!A10,IF(LEN('WBS Input'!B10)-LEN(SUBSTITUTE('WBS Input'!B10,".",""))<=1," ├─ "&'WBS Input'!C10," │ ├─ "&'WBS Input'!C10))) -> │ ├─ Identify Exception & Non-Standard Processes | C10: =IF(AND('WBS Input'!A10="",'WBS Input'!B10=""),"",IF('WBS Input'!A10<>"","",'WBS Input'!D10)) -> Identify undocumented special handling procedures | D10: =IF(AND('WBS Input'!A10="",'WBS Input'!B10=""),"",IF('WBS Input'!A10<>"","",IF('WBS Input'!E10="","",'WBS Input'!E10))) | E10: =IF(AND('WBS Input'!A10="",'WBS Input'!B10=""),"",IF('WBS Input'!A10<>"","",IF('WBS Input'!J10="","",'WBS Input'!J10)))
A11: =IF(AND('WBS Input'!A11="",'WBS Input'!B11=""),"",IF('WBS Input'!A11<>"","★",'WBS Input'!B11)) -> 1.1.5 | B11: =IF(AND('WBS Input'!A11="",'WBS Input'!B11=""),"",IF('WBS Input'!A11<>"","■ "&'WBS Input'!A11,IF(LEN('WBS Input'!B11)-LEN(SUBSTITUTE('WBS Input'!B11,".",""))<=1," ├─ "&'WBS Input'!C11," │ ├─ "&'WBS Input'!C11))) -> │ ├─ Review Social Insurance & Labor Insurance Operations | C11: =IF(AND('WBS Input'!A11="",'WBS Input'!B11=""),"",IF('WBS Input'!A11<>"","",'WBS Input'!D11)) -> Map health insurance and pension enrollment/disenrollment, standard remuneration, and monthly changes | D11: =IF(AND('WBS Input'!A11="",'WBS Input'!B11=""),"",IF('WBS Input'!A11<>"","",IF('WBS Input'!E11="","",'WBS Input'!E11))) | E11: =IF(AND('WBS Input'!A11="",'WBS Input'!B11=""),"",IF('WBS Input'!A11<>"","",IF('WBS Input'!J11="","",'WBS Input'!J11)))
A12: =IF(AND('WBS Input'!A12="",'WBS Input'!B12=""),"",IF('WBS Input'!A12<>"","★",'WBS Input'!B12)) -> 1.1.6 | B12: =IF(AND('WBS Input'!A12="",'WBS Input'!B12=""),"",IF('WBS Input'!A12<>"","■ "&'WBS Input'!A12,IF(LEN('WBS Input'!B12)-LEN(SUBSTITUTE('WBS Input'!B12,".",""))<=1," ├─ "&'WBS Input'!C12," │ ├─ "&'WBS Input'!C12))) -> │ ├─ Review Resignation & Leave of Absence Procedures | C12: =IF(AND('WBS Input'!A12="",'WBS Input'!B12=""),"",IF('WBS Input'!A12<>"","",'WBS Input'!D12)) -> Visualize severance pay calculations, separation certificates, parental/sick leave benefits | D12: =IF(AND('WBS Input'!A12="",'WBS Input'!B12=""),"",IF('WBS Input'!A12<>"","",IF('WBS Input'!E12="","",'WBS Input'!E12))) | E12: =IF(AND('WBS Input'!A12="",'WBS Input'!B12=""),"",IF('WBS Input'!A12<>"","",IF('WBS Input'!J12="","",'WBS Input'!J12)))
A13: =IF(AND('WBS Input'!A13="",'WBS Input'!B13=""),"",IF('WBS Input'!A13<>"","★",'WBS Input'!B13)) -> 1.1.7 | B13: =IF(AND('WBS Input'!A13="",'WBS Input'!B13=""),"",IF('WBS Input'!A13<>"","■ "&'WBS Input'!A13,IF(LEN('WBS Input'!B13)-LEN(SUBSTITUTE('WBS Input'!B13,".",""))<=1," ├─ "&'WBS Input'!C13," │ ├─ "&'WBS Input'!C13))) -> │ ├─ Review Benefits-Related Administrative Tasks | C13: =IF(AND('WBS Input'!A13="",'WBS Input'!B13=""),"",IF('WBS Input'!A13<>"","",'WBS Input'!D13)) -> Organize allowances, ESOP, savings plans, health check booking coordination, etc. | D13: =IF(AND('WBS Input'!A13="",'WBS Input'!B13=""),"",IF('WBS Input'!A13<>"","",IF('WBS Input'!E13="","",'WBS Input'!E13))) | E13: =IF(AND('WBS Input'!A13="",'WBS Input'!B13=""),"",IF('WBS Input'!A13<>"","",IF('WBS Input'!J13="","",'WBS Input'!J13)))
A14: =IF(AND('WBS Input'!A14="",'WBS Input'!B14=""),"",IF('WBS Input'!A14<>"","★",'WBS Input'!B14)) -> 1.1.8 | B14: =IF(AND('WBS Input'!A14="",'WBS Input'!B14=""),"",IF('WBS Input'!A14<>"","■ "&'WBS Input'!A14,IF(LEN('WBS Input'!B14)-LEN(SUBSTITUTE('WBS Input'!B14,".",""))<=1," ├─ "&'WBS Input'!C14," │ ├─ "&'WBS Input'!C14))) -> │ ├─ Review Year-End Tax Adjustment Processes | C14: =IF(AND('WBS Input'!A14="",'WBS Input'!B14=""),"",IF('WBS Input'!A14<>"","",'WBS Input'!D14)) -> Identify year-end adjustment schedule, filing systems, and e-filing usage | D14: =IF(AND('WBS Input'!A14="",'WBS Input'!B14=""),"",IF('WBS Input'!A14<>"","",IF('WBS Input'!E14="","",'WBS Input'!E14))) | E14: =IF(AND('WBS Input'!A14="",'WBS Input'!B14=""),"",IF('WBS Input'!A14<>"","",IF('WBS Input'!J14="","",'WBS Input'!J14)))
A15: =IF(AND('WBS Input'!A15="",'WBS Input'!B15=""),"",IF('WBS Input'!A15<>"","★",'WBS Input'!B15)) -> 1.1.9 | B15: =IF(AND('WBS Input'!A15="",'WBS Input'!B15=""),"",IF('WBS Input'!A15<>"","■ "&'WBS Input'!A15,IF(LEN('WBS Input'!B15)-LEN(SUBSTITUTE('WBS Input'!B15,".",""))<=1," ├─ "&'WBS Input'!C15," │ ├─ "&'WBS Input'!C15))) -> │ ├─ abcdef | C15: =IF(AND('WBS Input'!A15="",'WBS Input'!B15=""),"",IF('WBS Input'!A15<>"","",'WBS Input'!D15)) -> aaaaaa | D15: =IF(AND('WBS Input'!A15="",'WBS Input'!B15=""),"",IF('WBS Input'!A15<>"","",IF('WBS Input'!E15="","",'WBS Input'!E15))) | E15: =IF(AND('WBS Input'!A15="",'WBS Input'!B15=""),"",IF('WBS Input'!A15<>"","",IF('WBS Input'!J15="","",'WBS Input'!J15)))
A16: =IF(AND('WBS Input'!A16="",'WBS Input'!B16=""),"",IF('WBS Input'!A16<>"","★",'WBS Input'!B16)) -> 1.1.10 | B16: =IF(AND('WBS Input'!A16="",'WBS Input'!B16=""),"",IF('WBS Input'!A16<>"","■ "&'WBS Input'!A16,IF(LEN('WBS Input'!B16)-LEN(SUBSTITUTE('WBS Input'!B16,".",""))<=1," ├─ "&'WBS Input'!C16," │ ├─ "&'WBS Input'!C16))) -> │ ├─ ghijk | C16: =IF(AND('WBS Input'!A16="",'WBS Input'!B16=""),"",IF('WBS Input'!A16<>"","",'WBS Input'!D16)) -> bbbbbb | D16: =IF(AND('WBS Input'!A16="",'WBS Input'!B16=""),"",IF('WBS Input'!A16<>"","",IF('WBS Input'!E16="","",'WBS Input'!E16))) | E16: =IF(AND('WBS Input'!A16="",'WBS Input'!B16=""),"",IF('WBS Input'!A16<>"","",IF('WBS Input'!J16="","",'WBS Input'!J16)))
... A100: =IF(AND('WBS Input'!A100="",'WBS Input'!B100=""),"",IF('WBS Input'!A100<>"","★",'WBS Input'!B100)) | B100: =IF(AND('WBS Input'!A100="",'WBS Input'!B100=""),"",IF('WBS Input'!A100<>"","■ "&'WBS Input'!A100,IF(LEN('WBS Input'!B100)-LEN(SUBSTITUTE('WBS Input'!B100,".",""))<=1," ├─ "&'WBS Input'!C100," │ ├─ "&'WBS Input'!C100))) | C100: =IF(AND('WBS Input'!A100="",'WBS Input'!B100=""),"",IF('WBS Input'!A100<>"","",'WBS Input'!D100)) | D100: =IF(AND('WBS Input'!A100="",'WBS Input'!B100=""),"",IF('WBS Input'!A100<>"","",IF('WBS Input'!E100="","",'WBS Input'!E100))) | E100: =IF(AND('WBS Input'!A100="",'WBS Input'!B100=""),"",IF('WBS Input'!A100<>"","",IF('WBS Input'!J100="","",'WBS Input'!J100)))
A101: =IF(AND('WBS Input'!A95="",'WBS Input'!B95=""),"",IF('WBS Input'!A95<>"","★",'WBS Input'!B95)) | B101: =IF(AND('WBS Input'!A95="",'WBS Input'!B95=""),"",IF('WBS Input'!A95<>"","■ "&'WBS Input'!A95,IF(LEN('WBS Input'!B95)-LEN(SUBSTITUTE('WBS Input'!B95,".",""))<=1," ├─ "&'WBS Input'!C95," │ ├─ "&'WBS Input'!C95))) | C101: =IF(AND('WBS Input'!A95="",'WBS Input'!B95=""),"",IF('WBS Input'!A95<>"","",'WBS Input'!D95))

Sheet User Guide
A1: WBS User Guide
A3: ■ Sheet Structure
A4: Sheet Name | B4: Purpose | C4: Editing
A5: WBS Input | B5: Data entry and editing. All changes are made here. | C5: ○ Editable
A6: WBS Tree View | B6: Tree-format read-only view. Formulas automatically reference "WBS Input". | C6: ▲ Do not directly edit cells (formulas will break). Adding rows and copying formulas is OK.
A7: User Guide | B7: This sheet. Explains usage and maintenance procedures. | C7: -
A9: ■ How to Use the "WBS Input" Sheet
A11: Column Layout:
A12: Column A (Phase) | B12: Enter only the phase name. Example: "1. Planning & Current State Analysis"
A13: Column B (ID) | B13: WBS number. Example: 1.1 / 1.1.1 / 1.3.2
A14: Column C (Task Name) | B14: Name of the task
A15: Column D (Details) | B15: Description/definition of the task
A17: Row Types:
A18: Phase Row | B18: Enter the phase name in column A only. Leave columns B, C, and D blank.
A19: Mid-Level Task Row | B19: Enter ID (one dot) in column B. Example: 1.1 / 2.1 / 3.2
A20: Leaf Task Row | B20: Enter ID (two dots) in column B. Example: 1.1.1 / 3.2.2
A22: Important Rules:
A23: 1 | B23: Phase rows: only fill column A. Do not enter data in columns B, C, or D.
A24: 2 | B24: Task rows: leave column A blank and start entering from column B.
A25: 3 | B25: Place tasks directly below their phase (the order is reflected in the tree view).
A27: ■ Maintenance Procedures
A28: Action | B28: WBS Input Sheet | C28: WBS Tree View
A29: Change task name/details | B29: Edit column C or D in WBS Input sheet | C29: Auto-updated. No action needed.
A30: Change ID | B30: Edit column B in WBS Input sheet | C30: Auto-updated. Tree hierarchy adjusts automatically.
A31: Insert task between existing rows | B31: Insert a row in WBS Input sheet and enter data | C31: Auto-updated if within the formula reserve rows. Otherwise, extend formulas per instructions below.
A32: Add task at the end | B32: Add a row at the bottom of WBS Input sheet and enter data | C32: Row addition needed on Tree View side as well. See instructions below.
A33: Add a phase | B33: Add a phase row (column A only) and task rows | C33: Row addition needed on Tree View side as well. See instructions below.
A34: Delete a task | B34: Delete the row in WBS Input sheet | C34: Deleted rows will show #REF! errors. Copy formulas from a non-error row to fix the Tree View.
A36: ■ How to Extend Formulas in the WBS Tree View
A37: If WBS Input grows beyond the Tree View's formula reserve rows (whether appending or inserting), you need to extend the formula range on the Tree View side.
A39: Step 1: | B39: Open the WBS Tree View sheet
A40: Step 2: | B40: Select the last row that contains formulas
A41: Step 3: | B41: Select all 3 cells in columns A, B, and C, then drag the fill handle (■) down to the required number of rows
A42: Step 4: | B42: Formulas are copied to the new rows and WBS Input data is displayed automatically
A44: ※ If there are enough reserve rows, this step is not needed. The current formula range extends to row 100.
A46: ■ How the Tree View Works
A48: Symbol | B48: Level | C48: Detection Logic
A49: ■ | B49: Phase | C49: Row where column A (Phase) in WBS Input is not empty
A50: ├─ | B50: Mid-Level Task | C50: Column B ID has 1 or fewer dots (e.g., 1.1, 2.1)
A51: │ ├─ | B51: Leaf Task | C51: Column B ID has 2 or more dots (e.g., 1.1.1, 3.2.2)
...
