Workbook

Sheet WBS入力
A1: 人事業務BPOベンダー変更プロジェクト WBS | D1: Ver.0.1
D2: 46133
A4: フェーズ | B4: ID | C4: タスク名 | D4: 詳細内容 | E4: 担当者 | F4: 予定開始日 | G4: 予定完了日 | H4: 実績開始日 | I4: 実績完了日 | J4: ステータス | K4: タスク間依存関係メモ | L4: メモ
A5: 1. 企画・現状分析
B6: 1.1 | C6: 現状業務の棚卸し | D6: 対象業務の範囲（スコープ）の明確化 | E6: あおき | F6: 46113 | G6: 46143 | H6: 46113 | J6: 進行中
B7: 1.1.1 | C7: 現行業務フロー図の改訂 | D7: 給与・社保・勤怠のプロセスを最新化し可視化 | E7: あおき | F7: 46113 | G7: 46143 | H7: 46115 | J7: 進行中 | K7: 1.1.1（業務フロー図）完了後に実施が望ましい | L7: 全業務フロー図改定(1.1.1)と各業務棚卸し表(1.1.5以降)を別成果物として管理（大規模プロジェクト向き）。フロー図改訂の中で業務領域ごとに整理することも可能（小〜中規模向き）
B8: 1.1.2 | C8: 現行SLAの確認と実績評価 | D8: 現行ベンダーのパフォーマンスと未達項目の特定 | E8: うえだ | F8: 46113 | G8: 46127 | J8: 未着手 | K8: 1.1.1, 1.1.2 の成果物をインプットとする
B9: 1.1.3 | C9: 業務分担表（RACI）の作成 | D9: 自社人事・IT部門・現行ベンダー間の責任範囲を整理 | K9: 1.1.1 完了後に着手
B10: 1.1.4 | C10: 例外処理・イレギュラー業務の抽出 | D10: マニュアル化されていない特殊対応の特定
B11: 1.1.5 | C11: 社会保険・労働保険業務の確認 | D11: 健康保険・厚生年金の取得/喪失、算定、月変の運用把握 | L11: 1.1.5以降に各アウトソース業務を追加
B12: 1.1.6 | C12: 退職・休職手続きの確認 | D12: 退職金計算、離職票発行、育休・傷病手当運用の可視化
B13: 1.1.7 | C13: 福利厚生付帯業務の確認 | D13: 手当、持株会、財形、健康診断予約連携等の整理
B14: 1.1.8 | C14: 年末調整業務の確認 | D14: スケジュール、申告システム、電子申請利用状況の特定
B15: 1.1.9 | C15: abcdef | D15: あいうえお
B16: 1.1.10 | C16: ghijk | D16: かきくけこ
B17: 1.3 | C17: 予算・スケジュール策定 | D17: プロジェクト実行計画の承認取得
B18: 1.3.1 | C18: 切替コストの見積り | D18: 初期導入費用とランニングコストの比較 | K18: 1.1 全タスク完了が前提
B19: 1.3.2 | C19: プロジェクトロードマップ作成 | D19: RFP発行から本番稼働までの工程表作成 | K19: 1.3（予算・スケジュール）承認後に開始
B20: 1.3.3 | C20: リソース計画の策定 | D20: 内部メンバーの工数確保と体制構築 | K20: 2.1 の回答受領後に評価開始
A21: 2. ベンダー選定
B22: 2.1 | C22: RFI/RFP作成・送付 | D22: 提案依頼書の送付と質疑応答 | K22: 2.2（ベンダー選定）完了が前提
B23: 2.2 | C23: 提案評価・選定 | D23: プレゼン実施とスコアリングによる決定 | K23: 3.1（TO-BE設計）と並行可
A24: 3. 移管準備（設計）
B25: 3.1 | C25: TO-BE業務フロー設計 | D25: 新ベンダー体制での最適化
B26: 3.1.1 | C26: 業務フローのギャップ分析 | D26: 現行と新ベンダー標準機能の差分抽出
B27: 3.1.2 | C27: 承認ワークフローの再設計 | D27: 申請ルートとHRIS上の権限設定
B28: 3.2 | C28: システム/データ連携設計 | D28: データ整合性の担保
B29: 3.2.1 | C29: インターフェース仕様書の作成 | D29: HCM, 給与システム等との連携項目定義
B30: 3.2.2 | C30: マスターデータマッピング | D30: 組織コード等の名称・属性の突合定義 | K30: 3.1, 3.2, 3.3 すべて完了後に開始
B31: 3.3 | C31: 移行計画策定 | D31: 切替リスクの最小化
B32: 3.3.1 | C32: データクレンジング計画 | D32: 移行前に修正が必要な人事情報の特定 | K32: 4.1（UAT）合格が前提
B33: 3.3.2 | C33: パラレルラン（並行稼働）計画 | D33: 給与計算の二重検証期間、検証対象者の策定 | K33: 5.1（パラレルラン）の検証結果承認後に実施
A34: 4. 構築・テスト
B35: 4.1 | C35: 受入テスト（UAT） | D35: 業務シナリオに基づく運用テスト
A36: 5. 移行・並行稼働
B37: 5.1 | C37: パラレルラン実施 | D37: 現行と新ベンダーによる給与計算の突合
B38: 5.2 | C38: 本番切替（Go-Live） | D38: 新ベンダーへの完全移行
A39: 6. ABC
B40: 6.1 | C40: abcdef | D40: あいうえお
B41: 6.2 | C41: ghijk | D41: かきくけこ

Sheet WBSツリー表示
A1: =WBS入力!A1&"ツリー" -> 人事業務BPOベンダー変更プロジェクト WBSツリー | C1: =WBS入力!D1 -> Ver.0.1
C2: =WBS入力!D2 -> 46133
A4: ID | B4: フェーズ / タスク名 | C4: 詳細内容 | D4: 担当者 | E4: ステータス
A5: =IF(AND(WBS入力!A5="",WBS入力!B5=""),"",IF(WBS入力!A5<>"","★",WBS入力!B5)) -> ★ | B5: =IF(AND(WBS入力!A5="",WBS入力!B5=""),"",IF(WBS入力!A5<>"","■ "&WBS入力!A5,IF(LEN(WBS入力!B5)-LEN(SUBSTITUTE(WBS入力!B5,".",""))<=1," ├─ "&WBS入力!C5," │ ├─ "&WBS入力!C5))) -> ■ 1. 企画・現状分析 | C5: =IF(AND(WBS入力!A5="",WBS入力!B5=""),"",IF(WBS入力!A5<>"","",WBS入力!D5)) | D5: =IF(AND(WBS入力!A5="",WBS入力!B5=""),"",IF(WBS入力!A5<>"","",IF(WBS入力!E5="","",WBS入力!E5))) | E5: =IF(AND(WBS入力!A5="",WBS入力!B5=""),"",IF(WBS入力!A5<>"","",IF(WBS入力!J5="","",WBS入力!J5)))
A6: =IF(AND(WBS入力!A6="",WBS入力!B6=""),"",IF(WBS入力!A6<>"","★",WBS入力!B6)) -> 1.1 | B6: =IF(AND(WBS入力!A6="",WBS入力!B6=""),"",IF(WBS入力!A6<>"","■ "&WBS入力!A6,IF(LEN(WBS入力!B6)-LEN(SUBSTITUTE(WBS入力!B6,".",""))<=1," ├─ "&WBS入力!C6," │ ├─ "&WBS入力!C6))) -> ├─ 現状業務の棚卸し | C6: =IF(AND(WBS入力!A6="",WBS入力!B6=""),"",IF(WBS入力!A6<>"","",WBS入力!D6)) -> 対象業務の範囲（スコープ）の明確化 | D6: =IF(AND(WBS入力!A6="",WBS入力!B6=""),"",IF(WBS入力!A6<>"","",IF(WBS入力!E6="","",WBS入力!E6))) -> あおき | E6: =IF(AND(WBS入力!A6="",WBS入力!B6=""),"",IF(WBS入力!A6<>"","",IF(WBS入力!J6="","",WBS入力!J6))) -> 進行中
A7: =IF(AND(WBS入力!A7="",WBS入力!B7=""),"",IF(WBS入力!A7<>"","★",WBS入力!B7)) -> 1.1.1 | B7: =IF(AND(WBS入力!A7="",WBS入力!B7=""),"",IF(WBS入力!A7<>"","■ "&WBS入力!A7,IF(LEN(WBS入力!B7)-LEN(SUBSTITUTE(WBS入力!B7,".",""))<=1," ├─ "&WBS入力!C7," │ ├─ "&WBS入力!C7))) -> │ ├─ 現行業務フロー図の改訂 | C7: =IF(AND(WBS入力!A7="",WBS入力!B7=""),"",IF(WBS入力!A7<>"","",WBS入力!D7)) -> 給与・社保・勤怠のプロセスを最新化し可視化 | D7: =IF(AND(WBS入力!A7="",WBS入力!B7=""),"",IF(WBS入力!A7<>"","",IF(WBS入力!E7="","",WBS入力!E7))) -> あおき | E7: =IF(AND(WBS入力!A7="",WBS入力!B7=""),"",IF(WBS入力!A7<>"","",IF(WBS入力!J7="","",WBS入力!J7))) -> 進行中
A8: =IF(AND(WBS入力!A8="",WBS入力!B8=""),"",IF(WBS入力!A8<>"","★",WBS入力!B8)) -> 1.1.2 | B8: =IF(AND(WBS入力!A8="",WBS入力!B8=""),"",IF(WBS入力!A8<>"","■ "&WBS入力!A8,IF(LEN(WBS入力!B8)-LEN(SUBSTITUTE(WBS入力!B8,".",""))<=1," ├─ "&WBS入力!C8," │ ├─ "&WBS入力!C8))) -> │ ├─ 現行SLAの確認と実績評価 | C8: =IF(AND(WBS入力!A8="",WBS入力!B8=""),"",IF(WBS入力!A8<>"","",WBS入力!D8)) -> 現行ベンダーのパフォーマンスと未達項目の特定 | D8: =IF(AND(WBS入力!A8="",WBS入力!B8=""),"",IF(WBS入力!A8<>"","",IF(WBS入力!E8="","",WBS入力!E8))) -> うえだ | E8: =IF(AND(WBS入力!A8="",WBS入力!B8=""),"",IF(WBS入力!A8<>"","",IF(WBS入力!J8="","",WBS入力!J8))) -> 未着手
A9: =IF(AND(WBS入力!A9="",WBS入力!B9=""),"",IF(WBS入力!A9<>"","★",WBS入力!B9)) -> 1.1.3 | B9: =IF(AND(WBS入力!A9="",WBS入力!B9=""),"",IF(WBS入力!A9<>"","■ "&WBS入力!A9,IF(LEN(WBS入力!B9)-LEN(SUBSTITUTE(WBS入力!B9,".",""))<=1," ├─ "&WBS入力!C9," │ ├─ "&WBS入力!C9))) -> │ ├─ 業務分担表（RACI）の作成 | C9: =IF(AND(WBS入力!A9="",WBS入力!B9=""),"",IF(WBS入力!A9<>"","",WBS入力!D9)) -> 自社人事・IT部門・現行ベンダー間の責任範囲を整理 | D9: =IF(AND(WBS入力!A9="",WBS入力!B9=""),"",IF(WBS入力!A9<>"","",IF(WBS入力!E9="","",WBS入力!E9))) | E9: =IF(AND(WBS入力!A9="",WBS入力!B9=""),"",IF(WBS入力!A9<>"","",IF(WBS入力!J9="","",WBS入力!J9)))
A10: =IF(AND(WBS入力!A10="",WBS入力!B10=""),"",IF(WBS入力!A10<>"","★",WBS入力!B10)) -> 1.1.4 | B10: =IF(AND(WBS入力!A10="",WBS入力!B10=""),"",IF(WBS入力!A10<>"","■ "&WBS入力!A10,IF(LEN(WBS入力!B10)-LEN(SUBSTITUTE(WBS入力!B10,".",""))<=1," ├─ "&WBS入力!C10," │ ├─ "&WBS入力!C10))) -> │ ├─ 例外処理・イレギュラー業務の抽出 | C10: =IF(AND(WBS入力!A10="",WBS入力!B10=""),"",IF(WBS入力!A10<>"","",WBS入力!D10)) -> マニュアル化されていない特殊対応の特定 | D10: =IF(AND(WBS入力!A10="",WBS入力!B10=""),"",IF(WBS入力!A10<>"","",IF(WBS入力!E10="","",WBS入力!E10))) | E10: =IF(AND(WBS入力!A10="",WBS入力!B10=""),"",IF(WBS入力!A10<>"","",IF(WBS入力!J10="","",WBS入力!J10)))
A11: =IF(AND(WBS入力!A11="",WBS入力!B11=""),"",IF(WBS入力!A11<>"","★",WBS入力!B11)) -> 1.1.5 | B11: =IF(AND(WBS入力!A11="",WBS入力!B11=""),"",IF(WBS入力!A11<>"","■ "&WBS入力!A11,IF(LEN(WBS入力!B11)-LEN(SUBSTITUTE(WBS入力!B11,".",""))<=1," ├─ "&WBS入力!C11," │ ├─ "&WBS入力!C11))) -> │ ├─ 社会保険・労働保険業務の確認 | C11: =IF(AND(WBS入力!A11="",WBS入力!B11=""),"",IF(WBS入力!A11<>"","",WBS入力!D11)) -> 健康保険・厚生年金の取得/喪失、算定、月変の運用把握 | D11: =IF(AND(WBS入力!A11="",WBS入力!B11=""),"",IF(WBS入力!A11<>"","",IF(WBS入力!E11="","",WBS入力!E11))) | E11: =IF(AND(WBS入力!A11="",WBS入力!B11=""),"",IF(WBS入力!A11<>"","",IF(WBS入力!J11="","",WBS入力!J11)))
A12: =IF(AND(WBS入力!A12="",WBS入力!B12=""),"",IF(WBS入力!A12<>"","★",WBS入力!B12)) -> 1.1.6 | B12: =IF(AND(WBS入力!A12="",WBS入力!B12=""),"",IF(WBS入力!A12<>"","■ "&WBS入力!A12,IF(LEN(WBS入力!B12)-LEN(SUBSTITUTE(WBS入力!B12,".",""))<=1," ├─ "&WBS入力!C12," │ ├─ "&WBS入力!C12))) -> │ ├─ 退職・休職手続きの確認 | C12: =IF(AND(WBS入力!A12="",WBS入力!B12=""),"",IF(WBS入力!A12<>"","",WBS入力!D12)) -> 退職金計算、離職票発行、育休・傷病手当運用の可視化 | D12: =IF(AND(WBS入力!A12="",WBS入力!B12=""),"",IF(WBS入力!A12<>"","",IF(WBS入力!E12="","",WBS入力!E12))) | E12: =IF(AND(WBS入力!A12="",WBS入力!B12=""),"",IF(WBS入力!A12<>"","",IF(WBS入力!J12="","",WBS入力!J12)))
A13: =IF(AND(WBS入力!A13="",WBS入力!B13=""),"",IF(WBS入力!A13<>"","★",WBS入力!B13)) -> 1.1.7 | B13: =IF(AND(WBS入力!A13="",WBS入力!B13=""),"",IF(WBS入力!A13<>"","■ "&WBS入力!A13,IF(LEN(WBS入力!B13)-LEN(SUBSTITUTE(WBS入力!B13,".",""))<=1," ├─ "&WBS入力!C13," │ ├─ "&WBS入力!C13))) -> │ ├─ 福利厚生付帯業務の確認 | C13: =IF(AND(WBS入力!A13="",WBS入力!B13=""),"",IF(WBS入力!A13<>"","",WBS入力!D13)) -> 手当、持株会、財形、健康診断予約連携等の整理 | D13: =IF(AND(WBS入力!A13="",WBS入力!B13=""),"",IF(WBS入力!A13<>"","",IF(WBS入力!E13="","",WBS入力!E13))) | E13: =IF(AND(WBS入力!A13="",WBS入力!B13=""),"",IF(WBS入力!A13<>"","",IF(WBS入力!J13="","",WBS入力!J13)))
A14: =IF(AND(WBS入力!A14="",WBS入力!B14=""),"",IF(WBS入力!A14<>"","★",WBS入力!B14)) -> 1.1.8 | B14: =IF(AND(WBS入力!A14="",WBS入力!B14=""),"",IF(WBS入力!A14<>"","■ "&WBS入力!A14,IF(LEN(WBS入力!B14)-LEN(SUBSTITUTE(WBS入力!B14,".",""))<=1," ├─ "&WBS入力!C14," │ ├─ "&WBS入力!C14))) -> │ ├─ 年末調整業務の確認 | C14: =IF(AND(WBS入力!A14="",WBS入力!B14=""),"",IF(WBS入力!A14<>"","",WBS入力!D14)) -> スケジュール、申告システム、電子申請利用状況の特定 | D14: =IF(AND(WBS入力!A14="",WBS入力!B14=""),"",IF(WBS入力!A14<>"","",IF(WBS入力!E14="","",WBS入力!E14))) | E14: =IF(AND(WBS入力!A14="",WBS入力!B14=""),"",IF(WBS入力!A14<>"","",IF(WBS入力!J14="","",WBS入力!J14)))
A15: =IF(AND(WBS入力!A15="",WBS入力!B15=""),"",IF(WBS入力!A15<>"","★",WBS入力!B15)) -> 1.1.9 | B15: =IF(AND(WBS入力!A15="",WBS入力!B15=""),"",IF(WBS入力!A15<>"","■ "&WBS入力!A15,IF(LEN(WBS入力!B15)-LEN(SUBSTITUTE(WBS入力!B15,".",""))<=1," ├─ "&WBS入力!C15," │ ├─ "&WBS入力!C15))) -> │ ├─ abcdef | C15: =IF(AND(WBS入力!A15="",WBS入力!B15=""),"",IF(WBS入力!A15<>"","",WBS入力!D15)) -> あいうえお | D15: =IF(AND(WBS入力!A15="",WBS入力!B15=""),"",IF(WBS入力!A15<>"","",IF(WBS入力!E15="","",WBS入力!E15))) | E15: =IF(AND(WBS入力!A15="",WBS入力!B15=""),"",IF(WBS入力!A15<>"","",IF(WBS入力!J15="","",WBS入力!J15)))
A16: =IF(AND(WBS入力!A16="",WBS入力!B16=""),"",IF(WBS入力!A16<>"","★",WBS入力!B16)) -> 1.1.10 | B16: =IF(AND(WBS入力!A16="",WBS入力!B16=""),"",IF(WBS入力!A16<>"","■ "&WBS入力!A16,IF(LEN(WBS入力!B16)-LEN(SUBSTITUTE(WBS入力!B16,".",""))<=1," ├─ "&WBS入力!C16," │ ├─ "&WBS入力!C16))) -> │ ├─ ghijk | C16: =IF(AND(WBS入力!A16="",WBS入力!B16=""),"",IF(WBS入力!A16<>"","",WBS入力!D16)) -> かきくけこ | D16: =IF(AND(WBS入力!A16="",WBS入力!B16=""),"",IF(WBS入力!A16<>"","",IF(WBS入力!E16="","",WBS入力!E16))) | E16: =IF(AND(WBS入力!A16="",WBS入力!B16=""),"",IF(WBS入力!A16<>"","",IF(WBS入力!J16="","",WBS入力!J16)))
... A100: =IF(AND(WBS入力!A100="",WBS入力!B100=""),"",IF(WBS入力!A100<>"","★",WBS入力!B100)) | B100: =IF(AND(WBS入力!A100="",WBS入力!B100=""),"",IF(WBS入力!A100<>"","■ "&WBS入力!A100,IF(LEN(WBS入力!B100)-LEN(SUBSTITUTE(WBS入力!B100,".",""))<=1," ├─ "&WBS入力!C100," │ ├─ "&WBS入力!C100))) | C100: =IF(AND(WBS入力!A100="",WBS入力!B100=""),"",IF(WBS入力!A100<>"","",WBS入力!D100)) | D100: =IF(AND(WBS入力!A100="",WBS入力!B100=""),"",IF(WBS入力!A100<>"","",IF(WBS入力!E100="","",WBS入力!E100))) | E100: =IF(AND(WBS入力!A100="",WBS入力!B100=""),"",IF(WBS入力!A100<>"","",IF(WBS入力!J100="","",WBS入力!J100)))
A101: =IF(AND(WBS入力!A95="",WBS入力!B95=""),"",IF(WBS入力!A95<>"","★",WBS入力!B95)) | B101: =IF(AND(WBS入力!A95="",WBS入力!B95=""),"",IF(WBS入力!A95<>"","■ "&WBS入力!A95,IF(LEN(WBS入力!B95)-LEN(SUBSTITUTE(WBS入力!B95,".",""))<=1," ├─ "&WBS入力!C95," │ ├─ "&WBS入力!C95))) | C101: =IF(AND(WBS入力!A95="",WBS入力!B95=""),"",IF(WBS入力!A95<>"","",WBS入力!D95))

Sheet 使い方ガイド
A1: WBS 使い方ガイド
A3: ■ シート構成
A4: シート名 | B4: 役割 | C4: 編集
A5: WBS入力 | B5: データの入力・編集用。すべての変更はここで行う | C5: ○ 編集可
A6: WBSツリー表示 | B6: ツリー形式の閲覧用。数式で「WBS入力」を自動参照 | C6: ▲ セルの直接編集禁止（数式が壊れます）。行追加・数式コピーはOK
A7: 使い方ガイド | B7: 本シート。操作方法とメンテナンス手順の説明 | C7: -
A9: ■ 「WBS入力」シートの使い方
A11: 列構成：
A12: A列（フェーズ） | B12: フェーズ名のみ記入。例：「1. 企画・現状分析」
A13: B列（ID） | B13: WBS番号。例：1.1 / 1.1.1 / 1.3.2
A14: C列（タスク名） | B14: タスクの名称
A15: D列（詳細内容） | B15: タスクの説明・定義
A16: K列（タスク間依存関係メモ） | B16: タスクの依存関係に関するメモ・コメント
A18: 行の種類：
A19: フェーズ行 | B19: A列にフェーズ名を記入。B・C・D列は空欄にする
A20: 中間タスク行 | B20: B列にID（ドットが1つ）を記入。例：1.1 / 2.1 / 3.2
A21: 末端タスク行 | B21: B列にID（ドットが2つ）を記入。例：1.1.1 / 3.2.2
A23: 重要ルール：
A24: 1 | B24: フェーズ行はA列のみ記入。B・C・D列にデータを入れないこと
A25: 2 | B25: タスク行はA列を空欄にし、B列から記入すること
A26: 3 | B26: フェーズ行の直下にそのフェーズのタスクを並べること（順序がツリーに反映される）
A28: ■ メンテナンス方法
A29: 操作 | B29: WBS入力シート対応 | C29: WBSツリー側対応
A30: タスク名・詳細の変更 | B30: WBS入力シートのC列またはD列を編集 | C30: 自動反映される。作業不要
A31: IDの変更 | B31: WBS入力シートのB列を編集 | C31: 自動反映される。ツリーの階層も自動調整
A32: 既存行の間にタスク追加 | B32: WBS入力シートで行を挿入し、データを入力 | C32: ツリー側の数式予備行の範囲内であれば自動反映。超える場合は下記手順で数式を拡張
A33: 末尾にタスク追加 | B33: WBS入力シートの末尾に行を追加し、データを入力 | C33: ツリー側にも行追加が必要。下記手順参照
A34: フェーズの追加 | B34: フェーズ行（A列のみ）とタスク行を追加 | C34: ツリー側にも行追加が必要。下記手順参照
A35: タスクの削除 | B35: WBS入力シートで行を削除 | C35: 削除された行が#REF!エラーとなる。ツリー側数式の再設定(エラーのない行からコピー&ペースト)が必要。
A37: ■ 「WBSツリー表示」側で数式拡張が必要な場合の手順
A38: ツリー表示の数式予備行を超えてWBS入力に行が増えた場合（末尾追加・途中挿入とも）、ツリー側の数式範囲を広げる必要があります。
A40: 手順１： | B40: WBSツリー表示シートを開く
A41: 手順２： | B41: データ最終行（数式が入っている最後の行）を選択
A42: 手順３： | B42: A・B・C列の3セルを選択し、右下のフィルハンドル（■）を必要行数分下にドラッグ
A43: 手順４： | B43: 新しい行に数式がコピーされ、WBS入力のデータが自動表示される
A45: ※ 予備行に余裕があれば、この作業は不要です。現在の数式範囲は100行目までです。
A47: ■ ツリー表示の仕組み
A49: 表示記号 | B49: 階層 | C49: 判定ロジック
A50: ■ | B50: フェーズ | C50: WBS入力のA列（フェーズ）が空でない行
A51: ├─ | B51: 中間タスク | C51: B列のIDのドット数が1個以下（例：1.1、2.1）
...
